<mujoco model="xlerobot_one_arm_on_plane">
  <compiler angle="radian" meshdir="./assets/"/>
  <option timestep="0.002" gravity="0 0 -9.80665" integrator="implicitfast"/>
  <visual>
    <headlight diffuse="0.6 0.6 0.6" ambient="0.3 0.3 0.3" specular="0 0 0"/>
    <rgba haze="0.15 0.25 0.35 1"/>
    <global azimuth="120" elevation="-20"/>
  </visual>

  <asset>
    <texture type="skybox" builtin="gradient" rgb1="0.3 0.5 0.7" rgb2="0 0 0" width="512" height="3072"/>
    <texture type="2d" name="groundplane" builtin="flat" mark="edge"
             rgb1="0.1 0.1 0.1" rgb2="0.3 0.5 0.3" markrgb="0.8 0.8 0.8" width="300" height="300"/>
    <material name="groundplane" texture="groundplane" texuniform="true" texrepeat="5 5" reflectance="0.2"/>
    <material name="orange" rgba="1.0 0.331 0.0 1.0" specular="0.1" shininess="0.1"/>
    <material name="black"  rgba="0.1 0.1 0.1 1.0" specular="0.1" shininess="0.1"/>

    <mesh name="Rotation_Pitch"         file="Rotation_Pitch.stl"/>
    <mesh name="Rotation_Pitch_Motor"   file="Rotation_Pitch_Motor.stl"/>
    <mesh name="Upper_Arm"              file="Upper_Arm.stl"/>
    <mesh name="Upper_Arm_Motor"        file="Upper_Arm_Motor.stl"/>
    <mesh name="Lower_Arm"              file="Lower_Arm.stl"/>
    <mesh name="Lower_Arm_Motor"        file="Lower_Arm_Motor.stl"/>
    <mesh name="Wrist_Pitch_Roll"       file="Wrist_Pitch_Roll.stl"/>
    <mesh name="Wrist_Pitch_Roll_Motor" file="Wrist_Pitch_Roll_Motor.stl"/>
  </asset>

  <default>
    <default class="so_arm100">
      <joint frictionloss="0.1" armature="0.1"/>
      <position kp="50" dampratio="1" forcerange="-35 35" ctrlrange="-3.14158 3.14158"/>
      <default class="Rotation"><joint axis="0 1 0" range="-2.2 2.2"/></default>
      <default class="Pitch">   <joint axis="1 0 0" range="-3.14158 0.2"/></default>
      <default class="Elbow">   <joint axis="1 0 0" range="0 3.14158"/></default>
      <default class="Wrist_Pitch"><joint axis="1 0 0" range="-2.0 1.8"/></default>
      <default class="Wrist_Roll"> <joint axis="0 1 0" range="-3.14158 3.14158"/></default>
      <default class="visual">
        <geom type="mesh" contype="0" conaffinity="0" density="0" group="2" material="black"/>
        <default class="motor_visual"><geom material="black"/></default>
      </default>
      <default class="collision">
        <geom group="3" type="mesh"/>
      </default>
    </default>
  </default>

  <worldbody>
    <light pos="0 0 3" dir="0 0 -1" directional="true"/>
    <geom type="plane" size="5 5 0.05" material="groundplane"/>

    <!-- small visual platform -->
     <body name="ball" pos="0.38 -0.0 1.2">
                  <joint name="ball_free" type="free"/>
                  <inertial mass="0.05" pos="0 0 0" diaginertia="4.5e-06 4.5e-06 4.5e-06"/>
                  <geom type="sphere" size="0.015" density="1000" rgba="1 0 0 1"/>
                </body>
                
                
                
                
    <body name="platform" pos="0 0 0.82">
      <geom name="platform_top" type="box" size="0.10 0.10 0.005"
            pos="0 0 0" rgba="0.8 0.8 0.8 1"/>
    </body>

    <!-- arm base fixed to platform -->
    <body name="robot_base" pos="0 0 0.82">

      <body name="Rotation_Pitch_R" pos="0 0 0" quat="0.499998 0.5 0.500002 0.5">
        <inertial pos="-9.07886e-05 0.0590972 0.031089"
                  quat="0.363978 0.441169 -0.623108 0.533504"
                  mass="0.119226"
                  diaginertia="5.94278e-05 5.89975e-05 3.13712e-05"/>
        <joint name="Rotation_R" pos="0 0 0" axis="0 -1 0" range="-2.1 2.1"/>
        <geom type="mesh" mesh="Rotation_Pitch"       rgba="0.3 0.3 0.3 1"/>
        <geom type="mesh" mesh="Rotation_Pitch_Motor" rgba="0.3 0.3 0.3 1"/>

        <body name="Upper_Arm_2" pos="0 0.1025 0.0306" quat="0.707105 0.707108 0 0">
          <inertial pos="-1.72052e-05 0.0701802 0.00310545"
                    quat="0.50104 0.498994 -0.493562 0.50632"
                    mass="0.162409"
                    diaginertia="0.000213312 0.000167164 7.01522e-05"/>
          <joint name="Pitch_R" pos="0 0 0" axis="-1 0 0" range="-0.1 3.45"/>
          <geom type="mesh" mesh="Upper_Arm"       rgba="0.3 0.3 0.3 1"/>
          <geom type="mesh" mesh="Upper_Arm_Motor" rgba="0.3 0.3 0.3 1"/>

          <body name="Lower_Arm_2" pos="0 0.11257 0.028" quat="0.707105 -0.707108 0 0">
            <inertial pos="-0.00339604 0.00137796 0.0768007"
                      quat="0.701995 0.0787996 0.0645626 0.704859"
                      mass="0.147968"
                      diaginertia="0.000138803 0.000107748 4.84242e-05"/>
            <joint name="Elbow_R" pos="0 0 0" axis="1 0 0" range="-0.2 3.14159"/>
            <geom type="mesh" mesh="Lower_Arm"       rgba="0.3 0.3 0.3 1"/>
            <geom type="mesh" mesh="Lower_Arm_Motor" rgba="0.3 0.3 0.3 1"/>

            <body name="Wrist_Pitch_Roll_2" pos="0 0.0052 0.1349" quat="0.707105 -0.707108 0 0">
              <inertial pos="-0.00852653 -0.0352279 -2.34622e-05"
                        quat="-0.0522806 0.705235 0.0549524 0.704905"
                        mass="0.0661321"
                        diaginertia="3.45403e-05 2.39041e-05 1.94704e-05"/>
              <joint name="Wrist_Pitch_R" pos="0 0 0" axis="1 0 0" range="-1.8 1.8"/>
              <joint name="Wrist_Roll_R"  pos="0 0 0" axis="0 1 0" range="-3.14159 3.14159"/>
              <geom type="mesh" mesh="Wrist_Pitch_Roll"       rgba="0.3 0.3 0.3 1"/>
              <geom type="mesh" mesh="Wrist_Pitch_Roll_Motor" rgba="0.3 0.3 0.3 1"/>

              <!-- small concave box to hold balls -->
              <body name="ball_container" pos="0 -0.1 0.02">
                <geom name="container_base" type="box" size="0.03 0.03 0.005"
                      pos="0 0 0" rgba="0.8 0.6 0.4 1"/>
                <geom name="wall_front" type="box" size="0.03 0.005 0.02"
                      pos="0  0.03 0.015" rgba="0.8 0.6 0.4 1"/>
                <geom name="wall_back"  type="box" size="0.03 0.005 0.02"
                      pos="0 -0.03 0.015" rgba="0.8 0.6 0.4 1"/>
                <geom name="wall_left"  type="box" size="0.005 0.03 0.02"
                      pos="-0.03 0 0.015" rgba="0.8 0.6 0.4 1"/>
                <geom name="wall_right" type="box" size="0.005 0.03 0.02"
                      pos="0.03  0 0.015" rgba="0.8 0.6 0.4 1"/>

                <!-- a small ball, starting slightly above container so it will fall in -->


              </body>

            </body>
          </body>
        </body>
      </body>
    </body>
  </worldbody>

  <actuator>
    <position class="Rotation"    name="Rotation_R"    joint="Rotation_R"/>
    <position class="Pitch"       name="Pitch_R"       joint="Pitch_R"/>
    <position class="Elbow"       name="Elbow_R"       joint="Elbow_R"/>
    <position class="Wrist_Pitch" name="Wrist_Pitch_R" joint="Wrist_Pitch_R"/>
    <position class="Wrist_Roll"  name="Wrist_Roll_R"  joint="Wrist_Roll_R"/>
  </actuator>

  <keyframe>
    <!-- 投掷起始姿态: 7个DOF = ball(7) + arm_joints(5) -->
    <!-- ball: x y z qw qx qy qz, arm: Rotation_R Pitch_R Elbow_R Wrist_Pitch_R Wrist_Roll_R -->
    <key name="throwing_ready" 
         qpos="0.38 0.0 1.2 1.0 0.0 0.0 0.0 0.0 -0.5 1.5 0.0 0.0" 
         ctrl="0.0 -0.5 1.5 0.0 0.0"/>
    <key name="home" 
         qpos="0.38 0.0 1.2 1.0 0.0 0.0 0.0 0.0 0.0 0.0 0.0 0.0" 
         ctrl="0.0 0.0 0.0 0.0 0.0"/>
  </keyframe>
</mujoco>

